Workbook
Name ColorTable: 'Pricing Data'!$A$17:$B$21
Name CoverageTable: 'Pricing Data'!$A$10:$B$13
Name SizeTable: 'Pricing Data'!$A$3:$B$6

Sheet Invoice Template
A8: Innovative Brand Exposure Through Printed Shadenet Products
A10: Email: | B10: marketing@printedshade.co.za | D10: INVOICE
A11: Address: | B11: Unit 10, Celie Industrial Park Celie Rd, Retreat, Cape Town | D11: Invoice No: | E11: PS-2025-001
A12: Website: | B12: www.printedshade.co.za | D12: Date: | E12: 45903.425
A13: Contact: | B13: 082 331 5379 | D13: Due Date: | E13: 45933.425
A15: TAX INVOICE
A16: BILL TO: | D16: INVOICE DETAILS:
A18: Company: | B18: Isipani Construction (Pty) Ltd | D18: Email: | E18: {=IF(B18="","[Customer Email]",IFERROR(INDEX('Customer Database'!E:E,MATCH(B18,'Customer Database'!A:A,0)),"[Customer Email]"))} -> lyndall@isipani.co.za
A19: Client: | B19: {=IF(B18="","Yolande Hunter",IFERROR(INDEX('Customer Database'!C:C,MATCH(B18,'Customer Database'!A:A,0)),"Yolande Hunter"))} -> Lyndall Sheldon | D19: Contact: | E19: {=IF(B18="","[Contact Number]",IFERROR(INDEX('Customer Database'!D:D,MATCH(B18,'Customer Database'!A:A,0)),"[Contact Number]"))} -> 021 868 3008
A20: Address: | B20: {=IF(B18="","Woodstock",IFERROR(INDEX('Customer Database'!F:F,MATCH(B18,'Customer Database'!A:A,0)),"Woodstock"))} | D20: Payment Terms: | E20: Net 30 days
A21: VAT No: | B21: {=IF(B18="","[Customer VAT]",IFERROR(INDEX('Customer Database'!G:G,MATCH(B18,'Customer Database'!A:A,0)),"[Customer VAT]"))} -> 0
A23: Logo 1
A24: Name:
A26: Size: | B26: Medium | D26: Unit Price: | E26: =VLOOKUP(B26,SizeTable,2,FALSE)*VLOOKUP(B28,CoverageTable,2,FALSE)*VLOOKUP(B30,ColorTable,2,FALSE) -> 540
A28: Coverage: | B28: Medium | D28: Print Size (m): | E28: 2
D29: Print Height (m) | E29: 1.06
A30: Colors: | B30: 1 | D30: Total Number Of Prints: | E30: 10
D31: Number of Prints per roll: | E31: 10
D33: Line Total: | E33: =E26*E30 -> 5400
A35: Layout: | B35: =IF(AND(E28>0,E29>0,E30>0,E31>0)," "&E31&" prints per roll × "&E28&"m × "&E29&"m each, "&ROUND((50-(E28*E31))/(E31+1),2)&"m gaps ("&ROUND(E30/E31,0)&" rolls needed)"&IF(B54>E29,", Margins: "&ROUND((B54-E29)*100/2,0)&"cm top/bottom",""),"Enter all dimensions") -> 10 prints per roll × 2m × 1.06m each, 2.73m gaps (1 rolls needed), Margins: 37cm top/bottom
A36: Artwork Setup fee: | B36: 950
A37: Logo 2
A38: Name:
A40: Size: | B40: Small | D40: Unit Price: | E40: 0
A42: Coverage: | B42: Medium | D42: Print Size: | E42: 2
D43: Print Height: | E43: 1
A44: Colours: | B44: 2 | D44: Total Number Of Prints: | E44: 0
D45: Number of Prints per roll: | E45: 10
D47: Line Total: | E47: 0
A49: Layout: | B49: =IF(AND(E42>0,E43>0,E44>0,E45>0)," "&E45&" prints per roll × "&E42&"m × "&E43&"m each, "&ROUND((50-(E42*E45))/(E45+1),2)&"m gaps ("&ROUND(E44/E45,0)&" rolls needed)"&IF(B54>E43,", Margins: "&ROUND((B54-E43)*100/2,0)&"cm top/bottom",""),"Enter all dimensions") -> Enter all dimensions
A50: Artwork Setup fee: | B50: 0
A51: Shade Cloth
A52: Description: | B52: Shade Cloth Roll Black
A53: Quantity: | B53: 1 | D53: Unit Price: | E53: 2750
A54: Shade Cloth Size: | B54: 1.8 | D54: Line Total: | E54: =E53*B53 -> 2750
A58: Total Print Quantity: | B58: =E30+E44 -> 10
A59: Volume Discount Amount: | B59: =(E33+E47)*E68 -> 0
A66: Banking Details:
A67: Bank: | B67: [Your Bank] | D67: Print Jobs Subtotal: | E67: =E33+E47 -> 5400
A68: Account: | B68: [Account Number] | D68: Volume Discount Rate: | E68: =IF(B58>=200,0.15,IF(B58>=100,0.1,IF(B58>=50,0.05,IF(B58>=25,0.025,0)))) -> 0
...

Sheet Customer Database
A1: Client Name | B1: Company Type | C1: Primary Contact | D1: Phone | E1: Email | F1: Address | G1: VAT Number | H1: Total Revenue | I1: Last Order Value | J1: Average Order Value | K1: Payment Terms | L1: Credit Limit | M1: Outstanding Balance | N1: Client Status | O1: First Order Date | P1: Last Order Date | Q1: Total Orders | R1: Days Since Last Order | S1: Client Priority | T1: Client Tier | U1: Annual Revenue Potential | V1: Growth Trend | W1: Strategic Value | X1: Risk Level | Y1: Next Action | Z1: Preferred Colors | AA1: Standard Sizes | AB1: Typical Quantity | AC1: Lead Time Required | AD1: Quality Requirements | AE1: Special Instructions | AF1: Notes
A2: Washirika 3 Oaks | B2: Construction Company | C2: Yolande Hunter | D2: 021 671 6250 | E2: yolande@w3o.co.za | F2: 76 Strand Street, Woodstock | G2: 4520219694 | H2: 216114 | I2: 29325 | J2: 24013 | K2: 50% deposit, balance before dispatch | L2: 0 | M2: 0 | N2: Active | O2: 45408 | P2: 45743 | Q2: 9 | R2: 91 | S2: PLATINUM Client (9+ orders) | T2: PLATINUM | U2: 300000 | V2: Expanding | W2: CRITICAL - Partnership Development | X2: Low | Y2: Partnership expansion discussion | Z2: Green and white | AA2: 2000mm x 790mm | AB2: 40+ prints per order | AC2: 10-12 working days | AD2: High-quality outdoor durability | AE2: Two-color printing, Cape Town + Johannesburg operations | AF2: PLATINUM CLIENT - Most valuable client with true partnership potential. Multi-branch operations across Cape Town and Johannesburg.
A3: Isipani Construction (Pty) Ltd | B3: Construction Company | C3: Lyndall Sheldon | D3: 021 868 3008 | E3: lyndall@isipani.co.za | G3: 0 | H3: 125368 | I3: 49588 | J3: 25074 | K3: 50% deposit, balance before dispatch | L3: 0 | M3: 0 | N3: Active | O3: 45337 | P3: 45630 | Q3: 5 | R3: 204 | S3: VIP Client (5+ orders) | T3: VIP | U3: 150000 | V3: Growing order values | W3: HIGH - Potential PLATINUM | X3: Low | Y3: Follow-up after 6+ months silence | AC3: 10-12 working days | AD3: Premium grade construction | AE3: High-value orders, increasing sizes | AF3: VIP CLIENT - Highest average order value, growing from R24k to R49k orders. Premium construction client.
A4: Tri-Star Construction | B4: Construction Company | C4: Charmagne Monk | D4: 084 510 5692 | E4: charmagne@tri-star.co.za | G4: 0 | H4: 112010 | I4: 52900 | J4: 28003 | K4: 50% deposit, balance before dispatch | L4: 0 | M4: 0 | N4: Active | O4: 45727 | P4: 45821 | Q4: 4 | R4: 13 | S4: VIP Client (4+ orders) | T4: VIP | U4: 200000 | V4: Rapid expansion | W4: CRITICAL - Major growth potential | X4: Low | Y4: Capitalize on growth momentum | AC4: 10-12 working days | AD4: Standard construction | AE4: Recent R52k order indicates major expansion | AF4: BREAKTHROUGH CLIENT - Recent R52,900 order shows major project expansion. PLATINUM potential.
A5: Digi Worx CC | B5: Design/Media/Tech | C5: Masego Mogashane | D5: 031 492 5642 | E5: masego.mogashane.co.za | G5: 0 | H5: 106260 | I5: 106260 | J5: 106260 | K5: 50% deposit, balance before dispatch | L5: 0 | M5: 0 | N5: Active | O5: 45736 | P5: 45736 | Q5: 1 | R5: 98 | S5: CRITICAL - Tech Sector Breakthrough | T5: HIGH-POTENTIAL | U5: 400000 | V5: Unknown - needs immediate contact | W5: CRITICAL - Sector breakthrough | X5: HIGH - No follow-up | Y5: IMMEDIATE contact within 24 hours | AC5: 10-12 working days | AD5: Tech/Media grade | AE5: Largest single order in database | AF5: CRITICAL FOLLOW-UP - R106k tech order, zero follow-up since March. Durban-based, tech sector breakthrough.
A6: Boundary Secure Fencing PTY LTD | B6: Construction Company | C6: Bradley Oldfield | D6: 082 598 4410 | E6: brad@boundarysecure.co.za | G6: 0 | H6: 91911 | I6: 9521 | J6: 15318 | K6: 50% deposit, balance before dispatch | L6: 0 | M6: 0 | N6: Active | O6: 45391 | P6: 45772 | Q6: 6 | R6: 62 | S6: VIP Client (6+ orders) | T6: VIP | U6: 120000 | V6: Stable consistent | W6: HIGH - Property development specialist | X6: Low | Y6: Regular quarterly check-in | AC6: 10-12 working days | AD6: Property grade construction | AE6: Works with Sitari Country Estate projects | AF6: VIP CLIENT - Consistent repeat client specializing in property development. Works with Sitari Country Estate.
A7: Remey Construction (Pty) Ltd | B7: Construction Company | C7: Maruis Grobler | D7: 021 883 2616 | E7: buyer@remey.co.za | F7: 9 Papegaai Street, Stellenbosch, 7600 | G7: 4730202969 | H7: 89125 | I7: 3450 | J7: 11141 | K7: 50% deposit, balance before dispatch | L7: 0 | M7: 0 | N7: Active | O7: 45363 | P7: 45708 | Q7: 8 | R7: 126 | S7: VIP Client (8+ orders) | T7: VIP | U7: 100000 | V7: Stable frequent | W7: HIGH - Most frequent client | X7: Low | Y7: Relationship maintenance call | Z7: One colour | AA7: 2m x 0.3m | AB7: 39 logos per order | AC7: 10-12 working days | AD7: Standard construction | AE7: 5 prints per roll with 6.6m gaps | AF7: VIP CLIENT - Most frequent client (8 orders). Stellenbosch-based, reliable repeat business.
A8: Terbinex (PTY) Ltd | B8: Construction Company | C8: Kalla Laubscher | D8: 079 526 4256 | E8: kalla@plumbcore.co.za | G8: 0 | H8: 77280 | I8: 77280 | J8: 77280 | K8: 50% deposit, balance before dispatch | L8: 0 | M8: 0 | N8: Active | O8: 45551 | P8: 45551 | Q8: 1 | R8: 283 | S8: CRITICAL - Large Construction Opportunity | T8: HIGH-POTENTIAL | U8: 300000 | V8: Unknown - dormant 9+ months | W8: CRITICAL - Major construction opportunity | X8: HIGH - Long dormant | Y8: IMMEDIATE reactivation call | AC8: 10-12 working days | AD8: Standard construction | AE8: Zero follow-up since September 2024 | AF8: CRITICAL FOLLOW-UP - R77k order, 9+ months no contact. Major construction company opportunity.
A9: JNA Group (Pty) Ltd | B9: Construction Company | C9: Tania Schoeman | D9: 021 919 8397 | E9: buyer@jnagroup.co.za | G9: 0 | H9: 66309 | I9: 6670 | J9: 11052 | K9: 50% deposit, balance before dispatch | L9: 0 | M9: 0 | N9: Active | O9: 45569 | P9: 45789 | Q9: 6 | R9: 45 | S9: VIP Client (6+ orders) | T9: VIP | U9: 80000 | V9: Stable consistent | W9: HIGH - Multi-division group | X9: Low | Y9: Regular business development | AC9: 10-12 working days | AD9: Standard construction | AE9: Consolidated: Projects/Group/Thatchers divisions | AF9: VIP CLIENT - Multi-division construction group. Consolidated entity across Projects, Group, and Thatchers.
A10: Hot 1027 Pty Limited | B10: Design/Media | C10: Carmen Rocha | D10: 073 47 67 522 | E10: carmen@hot1027.co.za | G10: 0 | H10: 57040 | I10: 57040 | J10: 57040 | K10: 50% deposit, balance before dispatch | L10: 0 | M10: 0 | N10: Active | O10: 45560 | P10: 45560 | Q10: 1 | R10: 274 | S10: CRITICAL - Media Sector Expansion | T10: HIGH-POTENTIAL | U10: 200000 | V10: Unknown - dormant 9+ months | W10: CRITICAL - Media sector expansion | X10: HIGH - Long dormant | Y10: IMMEDIATE sector development call | AC10: 10-12 working days | AD10: Media/design grade | AE10: Media company - sector breakthrough potential | AF10: CRITICAL FOLLOW-UP - Media company, R57k order, 9 months dormant. Could unlock media sector.
A11: Growtime Construction | B11: Construction Company | C11: Stefan Botha | D11: 076 022 8809 | E11: stefan@builderscorner.co.za | G11: 0 | H11: 54270 | I11: 54270 | J11: 54270 | K11: 50% deposit, balance before dispatch | L11: 0 | M11: 0 | N11: Active | O11: 45322 | P11: 45322 | Q11: 1 | R11: 516 | S11: CRITICAL - Major Builder Recovery | T11: HIGH-POTENTIAL | U11: 250000 | V11: Unknown - severely dormant | W11: CRITICAL - Major builder recovery | X11: VERY HIGH - 17+ months dormant | Y11: IMMEDIATE relationship recovery call | AC11: 10-12 working days | AD11: Standard construction | AE11: 17+ months no contact - relationship recovery needed | AF11: CRITICAL RECOVERY - R54k construction order, 17 months no follow-up. Major builder relationship recovery.
A12: Multiknit (Pty) Ltd T/A Knittex | B12: Manufacturing | C12: Annelien Van Janse Renesburg | D12: 082 260 6788 | E12: buyer@knittex.co.za | G12: 0 | H12: 53493 | I12: 13662 | J12: 13373 | K12: 50% deposit, balance before dispatch | L12: 0 | M12: 0 | N12: Active | O12: 45405 | P12: 45705 | Q12: 4 | R12: 129 | S12: Regular Client (4+ orders) | T12: REGULAR | U12: 60000 | V12: Stable consistent | W12: MEDIUM - Manufacturing diversification | X12: Low | Y12: Regular business maintenance | AC12: 10-12 working days | AD12: Manufacturing grade | AE12: Non-construction client, textile applications | AF12: REGULAR CLIENT - Manufacturing sector diversification. Consistent repeat business, specialized niche.
A13: Skyfall Development Properties (PTY) LTD | B13: Property Developer | C13: Stefan Louw | D13: 072 845 6947 | E13: joann@skyfall.co.za | G13: 0 | H13: 41429 | I13: 41429 | J13: 41429 | K13: 50% deposit, balance before dispatch | L13: 0 | M13: 0 | N13: Active | O13: 45748 | P13: 45748 | Q13: 1 | R13: 86 | S13: High-Value Single Order | T13: OPPORTUNITY | U13: 120000 | V13: Unknown - needs follow-up | W13: HIGH - Property development sector | X13: Medium | Y13: Follow-up for repeat business | AC13: 10-12 working days | AD13: Property development grade | AE13: Large property development order | AF13: HIGH POTENTIAL - Large property development order. Represents growth opportunity in property sector.
A14: Capeprop Estates (Pty) Ltd | B14: Property Developer | C14: Malinda Fraser | D14: 021 701 2446 | E14: constantia@sothebysrealtyss.co.za | G14: 0 | H14: 37620 | I14: 37620 | J14: 37620 | K14: 50% deposit, balance before dispatch | L14: 0 | M14: 0 | N14: Active | O14: 45352 | P14: 45352 | Q14: 1 | R14: 481 | S14: High-Value Single Order | T14: OPPORTUNITY | U14: 100000 | V14: Unknown - long dormant | W14: MEDIUM - Property sector | X14: HIGH - Very long dormant | Y14: Reactivation after 16+ months | AC14: 10-12 working days | AD14: Property development grade | AE14: Property developer - needs reactivation | AF14: OPPORTUNITY - Property developer with R37k order but 16+ months dormant. Needs immediate reactivation.
A15: Plusnet/Geotex | B15: Construction Company | C15: Piet Buitendag | D15: 011 412 3954 | E15: pietbu@masterplasticsgroup.com | G15: 0 | H15: 37490 | I15: 37490 | J15: 37490 | K15: 50% deposit, balance before dispatch | L15: 0 | M15: 0 | N15: Active | O15: 45345 | P15: 45345 | Q15: 1 | R15: 487 | S15: High-Value Single Order | T15: OPPORTUNITY | U15: 80000 | V15: Unknown - long dormant | W15: MEDIUM - Industrial applications | X15: HIGH - Very long dormant | Y15: Reactivation after 16+ months | AC15: 10-12 working days | AD15: Industrial grade | AE15: Johannesburg-based industrial client | AF15: OPPORTUNITY - Industrial client R37k order, 16+ months dormant. Johannesburg presence, needs reactivation.
A16: Mimosa Arcade Holdings (Pty) Ltd | B16: Property Developer | C16: Gabrielle Weinstein | D16: 021 439 9030 | E16: gabi@bermanbros.co.za | G16: 0 | H16: 32373 | I16: 20470 | J16: 16186 | K16: 50% deposit, balance before dispatch | L16: 0 | M16: 0 | N16: Active | O16: 45446 | P16: 45463 | Q16: 2 | R16: 371 | S16: Repeat Client (2+ orders) | T16: REPEAT | U16: 50000 | V16: Early development | W16: MEDIUM - Property developer | X16: MEDIUM - Needs contact | Y16: Follow-up after 12+ months | AC16: 10-12 working days | AD16: Property development grade | AE16: Berman Bros Group - property development | AF16: REPEAT CLIENT - Property developer, part of Berman Bros Group. Two orders but needs reactivation after 12+ months.
A17: Phonic Properties (PTY) LTD | B17: Property Developer | C17: Sollie Potgieter | D17: 012 809 3990 | E17: sollie@pmagroup.co.za | G17: 0 | H17: 28118 | I17: 8683 | J17: 14059 | K17: 50% deposit, balance before dispatch | L17: 0 | M17: 0 | N17: Active | O17: 45716 | P17: 45726 | Q17: 2 | R17: 108 | S17: Repeat Client (2+ orders) | T17: REPEAT | U17: 50000 | V17: Early growth | W17: MEDIUM - Property development | X17: Medium | Y17: Business development call | AC17: 10-12 working days | AD17: Property development grade | AE17: PMA Group, Johannesburg-based | AF17: REPEAT CLIENT - Part of PMA Group, Johannesburg-based. Early growth indicators, property development focus.
A18: Aview (PTY) Ltd | B18: Property Developer | C18: Jess de Kock | D18: 060 528 6328 | E18: jess@manor.life | G18: 0 | H18: 27313 | I18: 27313 | J18: 27313 | K18: 50% deposit, balance before dispatch | L18: 0 | M18: 0 | N18: Active | O18: 45602 | P18: 45602 | Q18: 1 | R18: 232 | S18: High-Value Single Order | T18: OPPORTUNITY | U18: 60000 | V18: Unknown - dormant | W18: MEDIUM - Property sector | X18: MEDIUM - Needs contact | Y18: Property sector development call | AC18: 10-12 working days | AD18: Property development grade | AE18: Property developer, 7+ months dormant | AF18: OPPORTUNITY - Property developer with good R27k order. 7+ months dormant, needs follow-up for repeat business.
A19: Power Construction (Pty) Ltd | B19: Construction Company | C19: Zuriena Adams | D19: 021 907 1300 | G19: 0 | H19: 25530 | I19: 25530 | J19: 25530 | K19: 50% deposit, balance before dispatch | L19: 0 | M19: 0 | N19: Active | O19: 45422 | P19: 45422 | Q19: 1 | R19: 412 | S19: Medium-Value Single Order | T19: OPPORTUNITY | U19: 50000 | V19: Unknown - long dormant | W19: MEDIUM - Construction potential | X19: HIGH - Very long dormant | Y19: Reactivation call, get email address | AC19: 10-12 working days | AD19: Standard construction | AE19: Missing email address, long dormant | AF19: OPPORTUNITY - R25k construction order, 13+ months dormant. Missing email address, needs reactivation.
A20: Base Projects | B20: Construction Company | C20: Shihaam Behardien | D20: 021 447 5507 | E20: buying@baseprojects.co.za | G20: 0 | H20: 22540 | I20: 11270 | J20: 11270 | K20: 50% deposit, balance before dispatch | L20: 0 | M20: 0 | N20: Active | O20: 45418 | P20: 45468 | Q20: 2 | R20: 366 | S20: Repeat Client (2+ orders) | T20: REPEAT | U20: 40000 | V20: Stable small orders | W20: MEDIUM - Repeat potential | X20: MEDIUM - Needs contact | Y20: Follow-up after 12+ months | AC20: 10-12 working days | AD20: Standard construction | AE20: Two orders, needs reactivation | AF20: REPEAT CLIENT - Two orders totaling R22k. 12+ months since last contact, needs reactivation for repeat business.
A21: Faumba Holdings (Pty) Ltd t/a Longworth & Faul | B21: Construction Company | C21: Carmen Baron | D21: 021 862 2120 | E21: buyer@longworthfaul.co.za | F21: 16 Zuidmeer St, Huguenot, Paarl, 7646 | G21: 0 | H21: 37697 | I21: 9453 | J21: 12566 | K21: 50% deposit, balance before dispatch | L21: 0 | M21: 0 | N21: Active | O21: 45314 | P21: 45777 | Q21: 3 | R21: 57 | S21: Repeat Client (3+ orders) | T21: REPEAT | U21: 40000 | V21: Stable small orders | W21: MEDIUM - Geographic expansion | X21: Low | Y21: Regular maintenance contact | AC21: 10-12 working days | AD21: Standard construction | AE21: Paarl-based, multiple small orders | AF21: REPEAT CLIENT - Paarl-based client, 3 orders over time. Geographic diversification value, stable small orders.
A22: Transline Trading (PTY) LTD | B22: Construction Company | C22: Marcel Henle | E22: marcelhenle@gmail.com | G22: 0 | H22: 20298 | I22: 20298 | J22: 20298 | K22: 50% deposit, balance before dispatch | L22: 0 | M22: 0 | N22: Active | O22: 45789 | P22: 45789 | Q22: 1 | R22: 45 | S22: Medium-Value Single Order | T22: OPPORTUNITY | U22: 40000 | V22: Unknown - recent | W22: MEDIUM - Follow-up potential | X22: MEDIUM - Missing phone | Y22: Follow-up call, get phone number | AC22: 10-12 working days | AD22: Standard construction | AE22: Recent order, missing phone contact | AF22: OPPORTUNITY - Recent R20k order, missing phone number. Good follow-up potential for repeat business.
A23: Nexus Building Contractors (Pty) Ltd | B23: Construction Company | C23: Leonard le Roux | D23: +264 67 313770 | E23: leonard.leroux@nexusgroup.com.na | G23: 0 | H23: 20800 | I23: 20800 | J23: 20800 | K23: 50% deposit, balance before dispatch | L23: 0 | M23: 0 | N23: Active | O23: 45436 | P23: 45436 | Q23: 1 | R23: 398 | S23: Medium-Value Single Order | T23: OPPORTUNITY | U23: 45000 | V23: Unknown - long dormant | W23: MEDIUM - International expansion | X23: HIGH - Very long dormant | Y23: International client reactivation | AC23: 10-12 working days | AD23: Standard construction | AE23: Namibian client - international expansion | AF23: OPPORTUNITY - Namibian client R20k order, 13+ months dormant. International expansion potential.
A24: JDV Construction Boland | B24: Construction Company | C24: Jacques de Villiers | D24: 072 5206 903 | E24: jacques@jdv-construction.co.za | G24: 0 | H24: 18400 | I24: 18400 | J24: 18400 | K24: 50% deposit, balance before dispatch | L24: 0 | M24: 0 | N24: Active | O24: 45427 | P24: 45427 | Q24: 1 | R24: 407 | S24: Medium-Value Single Order | T24: OPPORTUNITY | U24: 35000 | V24: Unknown - long dormant | W24: MEDIUM - Regional expansion | X24: HIGH - Very long dormant | Y24: Regional client reactivation | AC24: 10-12 working days | AD24: Standard construction | AE24: Boland region client, needs reactivation | AF24: OPPORTUNITY - Boland region client R18k order, 13+ months dormant. Regional expansion potential.
A25: Evening Shade Properties 109 (Pty) Ltd | B25: Property Developer | C25: Russell Honeywill | D25: 083 600 2219 | E25: russ.cx@gmail.com | G25: 0 | H25: 17285 | I25: 17285 | J25: 17285 | K25: 50% deposit, balance before dispatch | L25: 0 | M25: 0 | N25: Active | O25: 45385 | P25: 45385 | Q25: 1 | R25: 449 | S25: Medium-Value Single Order | T25: OPPORTUNITY | U25: 40000 | V25: Unknown - long dormant | W25: MEDIUM - Property sector | X25: HIGH - Very long dormant | Y25: Property sector reactivation | AC25: 10-12 working days | AD25: Property development grade | AE25: Property developer, 14+ months dormant | AF25: OPPORTUNITY - Property developer R17k order, 14+ months dormant. Property sector reactivation needed.
A26: Wagters | B26: Construction Company | C26: Liezel Moller | D26: 082 958 9304 | E26: info@wagters.co.za | G26: 0 | H26: 16618 | I26: 16618 | J26: 16618 | K26: 50% deposit, balance before dispatch | L26: 0 | M26: 0 | N26: Active | O26: 45541 | P26: 45541 | Q26: 1 | R26: 293 | S26: Medium-Value Single Order | T26: OPPORTUNITY | U26: 35000 | V26: Unknown - long dormant | W26: MEDIUM - Conversion potential | X26: HIGH - Long dormant | Y26: Reactivation call | AC26: 10-12 working days | AD26: Standard construction | AE26: 9+ months dormant, decent order value | AF26: OPPORTUNITY - R16k order, 9+ months dormant. Decent conversion prospect if contacted promptly.
A27: Berrisford Construction | B27: Construction Company | C27: Sharilyn Meyer | D27: 021 447 9053 | E27: sharilyn@berrisfordconstruction.co.za | G27: 0 | H27: 16158 | I27: 16158 | J27: 16158 | K27: 50% deposit, balance before dispatch | L27: 0 | M27: 0 | N27: Active | O27: 45541 | P27: 45541 | Q27: 1 | R27: 293 | S27: Medium-Value Single Order | T27: OPPORTUNITY | U27: 32000 | V27: Unknown - long dormant | W27: MEDIUM - Construction potential | X27: HIGH - Long dormant | Y27: Construction sector follow-up | AC27: 10-12 working days | AD27: Standard construction | AE27: 9+ months dormant construction client | AF27: OPPORTUNITY - Construction client R16k order, 9+ months dormant. Good construction sector potential.
A28: Green Cube Construction | B28: Construction Company | C28: Marius Smit | D28: 082 909 2918 | E28: www.gc-group.co.za | G28: 0 | H28: 15870 | I28: 15870 | J28: 15870 | K28: 50% deposit, balance before dispatch | L28: 0 | M28: 0 | N28: Active | O28: 45429 | P28: 45429 | Q28: 1 | R28: 405 | S28: Medium-Value Single Order | T28: OPPORTUNITY | U28: 32000 | V28: Unknown - long dormant | W28: MEDIUM - Construction potential | X28: HIGH - Very long dormant | Y28: Reactivation, verify email format | AC28: 10-12 working days | AD28: Standard construction | AE28: Email appears to be website, needs verification | AF28: OPPORTUNITY - R15k construction order, 13+ months dormant. Email format needs verification (appears to be website).
A29: Trencon Construction | B29: Construction Company | C29: Anje Coetzee | D29: 010 0557280 | E29: anje@trencon.co.za | F29: Unit 9, Reserve 4,15 Capricorn Way | G29: 0 | H29: 13398 | I29: 12995 | J29: 6699 | K29: 50% deposit, balance before dispatch | L29: 0 | M29: 0 | N29: Active | O29: 45316 | P29: 45330 | Q29: 2 | R29: 503 | S29: Repeat Client (2+ orders) | T29: REPEAT | U29: 25000 | V29: Stable small orders | W29: LOW - Small orders | X29: HIGH - Very long dormant | Y29: Reactivation after 16+ months | AC29: 10-12 working days | AD29: Standard construction | AE29: Two small orders, 16+ months dormant | AF29: REPEAT CLIENT - Two small orders totaling R13k. 16+ months dormant, needs reactivation assessment.
A30: Afriline Civils | B30: Construction Company | C30: Rhuan Marais | D30: 079 892 0056 | E30: rhuan@afriline.co.za | G30: 0 | H30: 13570 | I30: 13570 | J30: 13570 | K30: 50% deposit, balance before dispatch | L30: 0 | M30: 0 | N30: Active | O30: 45420 | P30: 45420 | Q30: 1 | R30: 414 | S30: Medium-Value Single Order | T30: OPPORTUNITY | U30: 30000 | V30: Unknown - long dormant | W30: MEDIUM - Civil engineering niche | X30: HIGH - Very long dormant | Y30: Civil engineering sector follow-up | AC30: 10-12 working days | AD30: Civil engineering grade | AE30: Civil engineering contractor, 13+ months dormant | AF30: OPPORTUNITY - Civil engineering contractor R13k order, 13+ months dormant. Specialized niche potential.
A31: CS Property Group (Pty) Ltd | B31: Property Developer | C31: Colleen Ferguson | D31: 021 880 2672 | E31: colleen@csprop.co.za | G31: 0 | H31: 13668 | I31: 13668 | J31: 13668 | K31: 50% deposit, balance before dispatch | L31: 0 | M31: 0 | N31: Active | O31: 45342 | P31: 45342 | Q31: 1 | R31: 491 | S31: Medium-Value Single Order | T31: OPPORTUNITY | U31: 35000 | V31: Unknown - long dormant | W31: MEDIUM - Property sector | X31: HIGH - Very long dormant | Y31: Property sector reactivation | AC31: 10-12 working days | AD31: Property development grade | AE31: Property group, 16+ months dormant | AF31: OPPORTUNITY - Property group R13k order, 16+ months dormant. Property sector reactivation needed.
A32: Eddie Stemmet Bouers (PTY) LTD | B32: Construction Company | C32: Denise Stoop | D32: +27 23 614 1211 | E32: denise@esbou.co.za | G32: 0 | H32: 62878 | I32: 15238 | J32: 20959 | K32: 50% deposit, balance before dispatch | L32: 0 | M32: 0 | N32: Active | O32: 45345 | P32: 45573 | Q32: 3 | R32: 261 | S32: Repeat Client (3+ orders) | T32: REPEAT | U32: 50000 | V32: Stable medium orders | W32: MEDIUM - Regional presence | X32: MEDIUM - Needs contact | Y32: Reactivation after 8+ months | AC32: 10-12 working days | AD32: Standard construction | AE32: Regional construction, multiple entities | AF32: REPEAT CLIENT - Regional construction company, 3 orders totaling R62k. 8+ months since contact, needs reactivation.
A33: Valley Electrical Contractors Pty Ltd | B33: Electrical Contractor | C33: Petrie Korf | D33: 834522258 | E33: petrie@valleyelectrical.co.za | G33: 0 | H33: 12018 | I33: 12018 | J33: 12018 | K33: 50% deposit, balance before dispatch | L33: 0 | M33: 0 | N33: Active | O33: 45749 | P33: 45749 | Q33: 1 | R33: 85 | S33: Medium-Value Single Order | T33: OPPORTUNITY | U33: 30000 | V33: Unknown - recent | W33: MEDIUM - Specialized niche | X33: Medium | Y33: Specialized sector development | AC33: 10-12 working days | AD33: Electrical contractor grade | AE33: Electrical contractor, specialized niche | AF33: OPPORTUNITY - Electrical contractor R12k order, 2+ months since contact. Specialized niche market potential.
A34: R + N Master Builders Cape | B34: Construction Company | C34: Charles Adonis | D34: 021 422 3580 | E34: charles@r-n.co.za | G34: 0 | H34: 47656 | I34: 9660 | J34: 15885 | K34: 50% deposit, balance before dispatch | L34: 0 | M34: 0 | N34: Active | O34: 45369 | P34: 45525 | Q34: 3 | R34: 309 | S34: Repeat Client (3+ orders) | T34: REPEAT | U34: 40000 | V34: Stable medium orders | W34: MEDIUM - Repeat potential | X34: MEDIUM - Needs contact | Y34: Follow-up after 10+ months | AC34: 10-12 working days | AD34: Standard construction | AE34: 3 orders, 10+ months since contact | AF34: REPEAT CLIENT - 3 orders totaling R47k. 10+ months since last contact, needs reactivation for continued business.
A35: Stabilid Cape Construction (Pty) Ltd | B35: Construction Company | C35: Michael Lombard | D35: 021 982 8210 | E35: michael@stabilidcape.co.za | G35: 0 | H35: 21850 | I35: 11730 | J35: 10925 | K35: 50% deposit, balance before dispatch | L35: 0 | M35: 0 | N35: Active | O35: 45450 | P35: 45485 | Q35: 2 | R35: 349 | S35: Repeat Client (2+ orders) | T35: REPEAT | U35: 35000 | V35: Stable small orders | W35: MEDIUM - Industrial niche | X35: MEDIUM - Needs contact | Y35: Industrial sector follow-up | AC35: 10-12 working days | AD35: Industrial construction grade | AE35: Industrial construction, 11+ months dormant | AF35: REPEAT CLIENT - Industrial construction client, 2 orders totaling R21k. 11+ months dormant, industrial niche focus.
A36: Cape Estates Building Project (Pty) Ltd | B36: Construction Company | C36: Flip Le Roux | E36: capeconstruction@capeestates.co.za | G36: 0 | H36: 8924 | I36: 8924 | J36: 8924 | K36: 50% deposit, balance before dispatch | L36: 0 | M36: 0 | N36: Active | O36: 45330 | P36: 45330 | Q36: 1 | R36: 503 | S36: Medium-Value Single Order | T36: OPPORTUNITY | U36: 25000 | V36: Unknown - long dormant | W36: LOW - Small order | X36: HIGH - Very long dormant | Y36: Reactivation, get phone number | AC36: 10-12 working days | AD36: Standard construction | AE36: Missing phone, 16+ months dormant | AF36: OPPORTUNITY - R8k order, missing phone number, 16+ months dormant. Low priority reactivation.
A37: Devmark Building (Pty) Ltd | B37: Construction Company | C37: Shanaaz Fredericks | D37: 021 948 3502 | E37: sfredericks@devmark.co.za | G37: 0 | H37: 3335 | I37: 3335 | J37: 3335 | K37: 50% deposit, balance before dispatch | L37: 0 | M37: 0 | N37: Active | O37: 45335 | P37: 45335 | Q37: 1 | R37: 498 | S37: Small Single Order | T37: WATCH | U37: 15000 | V37: Unknown - long dormant | W37: LOW - Small order | X37: HIGH - Very long dormant | Y37: Low priority follow-up | AC37: 10-12 working days | AD37: Standard construction | AE37: Small order, 16+ months dormant | AF37: WATCH - Small R3k order, 16+ months dormant. Low priority for follow-up resources.
A38: Indawo Cape (Pty) Ltd | B38: Construction Company | C38: Shaun Meintjies | D38: 076 231 9092 | E38: shaun@indawo.biz | G38: 0 | H38: 2300 | I38: 2300 | J38: 2300 | K38: 50% deposit, balance before dispatch | L38: 0 | M38: 0 | N38: Active | O38: 45443 | P38: 45443 | Q38: 1 | R38: 391 | S38: Small Single Order | T38: WATCH | U38: 10000 | V38: Unknown - long dormant | W38: LOW - Very small order | X38: HIGH - Very long dormant | Y38: Monitor only | AC38: 10-12 working days | AD38: Standard construction | AE38: Very small order, 13+ months dormant | AF38: WATCH - Very small R2k order, 13+ months dormant. Monitor only, lowest priority.
A39: Plans 123 Pty Ltd | B39: Construction Company | C39: Anneke Schriek | D39: 082 470 0342 | E39: anneke@schriek.co.za | G39: 0 | H39: 288 | I39: 288 | J39: 288 | K39: 50% deposit, balance before dispatch | L39: 0 | M39: 0 | N39: Active | O39: 45385 | P39: 45385 | Q39: 1 | R39: 449 | S39: Small Single Order | T39: WATCH | U39: 5000 | V39: Unknown - long dormant | W39: LOW - Test order | X39: HIGH - Very long dormant | Y39: Monitor only | AC39: 10-12 working days | AD39: Standard construction | AE39: Test/sample order, 14+ months dormant | AF39: WATCH - Very small R288 test order, 14+ months dormant. Likely sample/test order only.
A40: Envirosails Pty Ltd TA Cape Shade CPT | B40: Shade Solutions | C40: Nicholas Adams | D40: 073 213 8163 | E40: engineering@capeshadecpt.co.za | G40: 0 | H40: 3278 | I40: 3278 | J40: 3278 | K40: 50% deposit, balance before dispatch | L40: 0 | M40: 0 | N40: Active | O40: 45720 | P40: 45720 | Q40: 1 | R40: 114 | S40: Competitive Client | T40: WATCH | U40: 10000 | V40: Unknown - competitor | W40: LOW - Potential competitor | X40: HIGH - Competitive threat | Y40: Competitive intelligence monitoring | AC40: 10-12 working days | AD40: Shade solutions grade | AE40: Potential competitor in shade solutions | AF40: COMPETITIVE - Potential competitor in shade solutions. Small order suggests market testing. Monitor for competitive intelligence.
...

Sheet Pricing Data
A1: Size Categories & Base Prices:
A2: Size Category | B2: Base Price (R)
A3: Small | B3: 350
A4: Medium | B4: 450
A5: Large | B5: 550
A6: XLarge | B6: 750
A8: Ink Coverage Multipliers:
A9: Coverage Level | B9: Multiplier
A10: Low | B10: 1
A11: Medium | B11: 1.2
A12: High | B12: 1.4
A13: Full | B13: 1.6
A15: Color Multipliers:
A16: Colors | B16: Multiplier
A17: 1 | B17: 1
A18: 2 | B18: 1.25
A19: 3 | B19: 1.5
A20: 4 | B20: 1.75
A21: 5 | B21: 2

Sheet Instructions
A1: PRINTED SHADE INVOICE TEMPLATE
A2: USER INSTRUCTIONS
A4: Step 1: Enter Customer Details
A5: • Company name in B14
A6: • Contact person in B15
A7: • Full address in B16
A8: • VAT number in B17 (if applicable)
A9: • Email and phone in F14, F17
A11: Step 2: Configure Print Jobs
A12: • Job 1: Rows 19-29
A13: • Job 2: Rows 31-41
A14: • Job 3: Rows 43-53
... A29: VOLUME DISCOUNT RATES
A30: 5-9 prints: | B30: 5% discount
A31: 10-19 prints: | B31: 10% discount
A32: 20+ prints: | B32: 15% discount
A34: FORMULA REFERENCE
A35: Unit Price: | B35: =VLOOKUP(Size,SizeTable,2,0)*VLOOKUP(Coverage,CoverageTable,2,0)*VLOOKUP(Colors,ColorTable,2,0)
A36: Line Total: | B36: =Unit Price * Quantity
A37: Volume Discount: | B37: =IF(TotalQty>=20,0.15,IF(TotalQty>=10,0.1,IF(TotalQty>=5,0.05,0)))
A38: VAT: | B38: =Subtotal * 0.15
